data/sample_ticks.csv
timestamp_ns,event,order_id,side,price,quantity
1000000,A,1,B,99.50,100
1000100,A,2,S,100.00,50
1000200,A,3,B,99.75,200
1000300,A,4,S,100.25,75
1000400,E,2,S,100.00,25
1000500,A,5,B,99.50,150
1000600,X,1,B,99.50,0
1000700,A,6,S,100.00,30
1000800,E,4,S,100.25,75
1000900,A,7,B,100.00,500
